Workbook

Sheet SVI_MHDI
A1: city_name | B1: UF | C1: ibge_cod | D1: GADM_GID_2 | E1: pop_2020 | F1: MHDI_tot | G1: MHDI_long | H1: MHDI_edu | I1: MHDI_inc | J1: SVI_tot | K1: SVI_inf | L1: SVI_hum | M1: SVI_wrk | N1: SVI_quantiles
A2: =SVI!F2 -> Corumbiara/RO | B2: =INDEX(tb_SVI[],MATCH(Table3[[#This Row],[ibge_cod]],tb_SVI[Município],0),1) -> RO | C2: =INDEX(tb_SVI[],MATCH(Table3[[#This Row],[city_name]],tb_SVI[city_name_uf],0),3) -> 1100072 | D2: BRA.22.15_1 | E2: =INDEX(tb_SVI[],MATCH(Table3[[#This Row],[city_name]],tb_SVI[city_name_uf],0),5) -> 7220 | F2: =INDEX(tb_MHDI[],MATCH(Table3[[#This Row],[city_name]],tb_MHDI[mun_uf],0),5) -> 0.613 | G2: =INDEX(tb_MHDI[],MATCH(Table3[[#This Row],[city_name]],tb_MHDI[mun_uf],0),6) -> 0.63 | H2: =INDEX(tb_MHDI[],MATCH(Table3[[#This Row],[city_name]],tb_MHDI[mun_uf],0),7) -> 0.774 | I2: =INDEX(tb_MHDI[],MATCH(Table3[[#This Row],[city_name]],tb_MHDI[mun_uf],0),8) -> 0.473 | J2: =_xlfn.NUMBERVALUE(INDEX(tb_SVI[],MATCH(Table3[[#This Row],[city_name]],tb_SVI[city_name_uf],0),8),".") -> 0.336 | K2: =_xlfn.NUMBERVALUE(INDEX(tb_SVI[],MATCH(Table3[[#This Row],[city_name]],tb_SVI[city_name_uf],0),9),".") -> 0.201 | L2: =_xlfn.NUMBERVALUE(INDEX(tb_SVI[],MATCH(Table3[[#This Row],[city_name]],tb_SVI[city_name_uf],0),10),".") -> 0.427 | M2: =_xlfn.NUMBERVALUE(INDEX(tb_SVI[],MATCH(Table3[[#This Row],[city_name]],tb_SVI[city_name_uf],0),11),".") -> 0.381 | N2: =_xlfn.PERCENTRANK.INC(Table3[MHDI_tot],Table3[[#This Row],[MHDI_tot]],3) -> 0.305 | P2: min | Q2: =_xlfn.QUARTILE.INC(Table3[MHDI_tot],0) -> 0.418
A3: =SVI!F3 -> Colorado do Oeste/RO | B3: =INDEX(tb_SVI[],MATCH(Table3[[#This Row],[ibge_cod]],tb_SVI[Município],0),1) -> RO | C3: =INDEX(tb_SVI[],MATCH(Table3[[#This Row],[city_name]],tb_SVI[city_name_uf],0),3) -> 1100064 | D3: BRA.22.14_1 | E3: =INDEX(tb_SVI[],MATCH(Table3[[#This Row],[city_name]],tb_SVI[city_name_uf],0),5) -> 15544 | F3: =INDEX(tb_MHDI[],MATCH(Table3[[#This Row],[city_name]],tb_MHDI[mun_uf],0),5) -> 0.685 | G3: =INDEX(tb_MHDI[],MATCH(Table3[[#This Row],[city_name]],tb_MHDI[mun_uf],0),6) -> 0.676 | H3: =INDEX(tb_MHDI[],MATCH(Table3[[#This Row],[city_name]],tb_MHDI[mun_uf],0),7) -> 0.814 | I3: =INDEX(tb_MHDI[],MATCH(Table3[[#This Row],[city_name]],tb_MHDI[mun_uf],0),8) -> 0.584 | J3: =_xlfn.NUMBERVALUE(INDEX(tb_SVI[],MATCH(Table3[[#This Row],[city_name]],tb_SVI[city_name_uf],0),8),".") -> 0.28 | K3: =_xlfn.NUMBERVALUE(INDEX(tb_SVI[],MATCH(Table3[[#This Row],[city_name]],tb_SVI[city_name_uf],0),9),".") -> 0.114 | L3: =_xlfn.NUMBERVALUE(INDEX(tb_SVI[],MATCH(Table3[[#This Row],[city_name]],tb_SVI[city_name_uf],0),10),".") -> 0.394 | M3: =_xlfn.NUMBERVALUE(INDEX(tb_SVI[],MATCH(Table3[[#This Row],[city_name]],tb_SVI[city_name_uf],0),11),".") -> 0.333 | N3: =_xlfn.PERCENTRANK.INC(Table3[MHDI_tot],Table3[[#This Row],[MHDI_tot]],3) -> 0.581 | P3: 0.25 | Q3: =_xlfn.QUARTILE.INC(Table3[MHDI_tot],1) -> 0.599
A4: =SVI!F4 -> Chupinguaia/RO | B4: =INDEX(tb_SVI[],MATCH(Table3[[#This Row],[ibge_cod]],tb_SVI[Município],0),1) -> RO | C4: =INDEX(tb_SVI[],MATCH(Table3[[#This Row],[city_name]],tb_SVI[city_name_uf],0),3) -> 1100924 | D4: BRA.22.13_1 | E4: =INDEX(tb_SVI[],MATCH(Table3[[#This Row],[city_name]],tb_SVI[city_name_uf],0),5) -> 11472 | F4: =INDEX(tb_MHDI[],MATCH(Table3[[#This Row],[city_name]],tb_MHDI[mun_uf],0),5) -> 0.652 | G4: =INDEX(tb_MHDI[],MATCH(Table3[[#This Row],[city_name]],tb_MHDI[mun_uf],0),6) -> 0.659 | H4: =INDEX(tb_MHDI[],MATCH(Table3[[#This Row],[city_name]],tb_MHDI[mun_uf],0),7) -> 0.82 | I4: =INDEX(tb_MHDI[],MATCH(Table3[[#This Row],[city_name]],tb_MHDI[mun_uf],0),8) -> 0.514 | J4: =_xlfn.NUMBERVALUE(INDEX(tb_SVI[],MATCH(Table3[[#This Row],[city_name]],tb_SVI[city_name_uf],0),8),".") -> 0.338 | K4: =_xlfn.NUMBERVALUE(INDEX(tb_SVI[],MATCH(Table3[[#This Row],[city_name]],tb_SVI[city_name_uf],0),9),".") -> 0.285 | L4: =_xlfn.NUMBERVALUE(INDEX(tb_SVI[],MATCH(Table3[[#This Row],[city_name]],tb_SVI[city_name_uf],0),10),".") -> 0.383 | M4: =_xlfn.NUMBERVALUE(INDEX(tb_SVI[],MATCH(Table3[[#This Row],[city_name]],tb_SVI[city_name_uf],0),11),".") -> 0.347 | N4: =_xlfn.PERCENTRANK.INC(Table3[MHDI_tot],Table3[[#This Row],[MHDI_tot]],3) -> 0.445 | P4: 0.5 | Q4: =_xlfn.QUARTILE.INC(Table3[MHDI_tot],2) -> 0.665
A5: =SVI!F5 -> Vilhena/RO | B5: =INDEX(tb_SVI[],MATCH(Table3[[#This Row],[ibge_cod]],tb_SVI[Município],0),1) -> RO | C5: =INDEX(tb_SVI[],MATCH(Table3[[#This Row],[city_name]],tb_SVI[city_name_uf],0),3) -> 1100304 | D5: BRA.22.51_1 | E5: =INDEX(tb_SVI[],MATCH(Table3[[#This Row],[city_name]],tb_SVI[city_name_uf],0),5) -> 102211 | F5: =INDEX(tb_MHDI[],MATCH(Table3[[#This Row],[city_name]],tb_MHDI[mun_uf],0),5) -> 0.731 | G5: =INDEX(tb_MHDI[],MATCH(Table3[[#This Row],[city_name]],tb_MHDI[mun_uf],0),6) -> 0.734 | H5: =INDEX(tb_MHDI[],MATCH(Table3[[#This Row],[city_name]],tb_MHDI[mun_uf],0),7) -> 0.808 | I5: =INDEX(tb_MHDI[],MATCH(Table3[[#This Row],[city_name]],tb_MHDI[mun_uf],0),8) -> 0.659 | J5: =_xlfn.NUMBERVALUE(INDEX(tb_SVI[],MATCH(Table3[[#This Row],[city_name]],tb_SVI[city_name_uf],0),8),".") -> 0.239 | K5: =_xlfn.NUMBERVALUE(INDEX(tb_SVI[],MATCH(Table3[[#This Row],[city_name]],tb_SVI[city_name_uf],0),9),".") -> 0.103 | L5: =_xlfn.NUMBERVALUE(INDEX(tb_SVI[],MATCH(Table3[[#This Row],[city_name]],tb_SVI[city_name_uf],0),10),".") -> 0.339 | M5: =_xlfn.NUMBERVALUE(INDEX(tb_SVI[],MATCH(Table3[[#This Row],[city_name]],tb_SVI[city_name_uf],0),11),".") -> 0.274 | N5: =_xlfn.PERCENTRANK.INC(Table3[MHDI_tot],Table3[[#This Row],[MHDI_tot]],3) -> 0.816 | P5: 0.75 | Q5: =_xlfn.QUARTILE.INC(Table3[MHDI_tot],3) -> 0.718
A6: =SVI!F6 -> Vale do Paraíso/RO | B6: =INDEX(tb_SVI[],MATCH(Table3[[#This Row],[ibge_cod]],tb_SVI[Município],0),1) -> RO | C6: =INDEX(tb_SVI[],MATCH(Table3[[#This Row],[city_name]],tb_SVI[city_name_uf],0),3) -> 1101807 | D6: BRA.22.50_1 | E6: =INDEX(tb_SVI[],MATCH(Table3[[#This Row],[city_name]],tb_SVI[city_name_uf],0),5) -> 6656 | F6: =INDEX(tb_MHDI[],MATCH(Table3[[#This Row],[city_name]],tb_MHDI[mun_uf],0),5) -> 0.627 | G6: =INDEX(tb_MHDI[],MATCH(Table3[[#This Row],[city_name]],tb_MHDI[mun_uf],0),6) -> 0.641 | H6: =INDEX(tb_MHDI[],MATCH(Table3[[#This Row],[city_name]],tb_MHDI[mun_uf],0),7) -> 0.792 | I6: =INDEX(tb_MHDI[],MATCH(Table3[[#This Row],[city_name]],tb_MHDI[mun_uf],0),8) -> 0.485 | J6: =_xlfn.NUMBERVALUE(INDEX(tb_SVI[],MATCH(Table3[[#This Row],[city_name]],tb_SVI[city_name_uf],0),8),".") -> 0.309 | K6: =_xlfn.NUMBERVALUE(INDEX(tb_SVI[],MATCH(Table3[[#This Row],[city_name]],tb_SVI[city_name_uf],0),9),".") -> 0.131 | L6: =_xlfn.NUMBERVALUE(INDEX(tb_SVI[],MATCH(Table3[[#This Row],[city_name]],tb_SVI[city_name_uf],0),10),".") -> 0.438 | M6: =_xlfn.NUMBERVALUE(INDEX(tb_SVI[],MATCH(Table3[[#This Row],[city_name]],tb_SVI[city_name_uf],0),11),".") -> 0.358 | N6: =_xlfn.PERCENTRANK.INC(Table3[MHDI_tot],Table3[[#This Row],[MHDI_tot]],3) -> 0.36 | P6: max | Q6: =_xlfn.QUARTILE.INC(Table3[MHDI_tot],4) -> 0.862
A7: =SVI!F7 -> Vale do Anari/RO | B7: =INDEX(tb_SVI[],MATCH(Table3[[#This Row],[ibge_cod]],tb_SVI[Município],0),1) -> RO | C7: =INDEX(tb_SVI[],MATCH(Table3[[#This Row],[city_name]],tb_SVI[city_name_uf],0),3) -> 1101757 | D7: BRA.22.49_1 | E7: =INDEX(tb_SVI[],MATCH(Table3[[#This Row],[city_name]],tb_SVI[city_name_uf],0),5) -> 11377 | F7: =INDEX(tb_MHDI[],MATCH(Table3[[#This Row],[city_name]],tb_MHDI[mun_uf],0),5) -> 0.584 | G7: =INDEX(tb_MHDI[],MATCH(Table3[[#This Row],[city_name]],tb_MHDI[mun_uf],0),6) -> 0.626 | H7: =INDEX(tb_MHDI[],MATCH(Table3[[#This Row],[city_name]],tb_MHDI[mun_uf],0),7) -> 0.756 | I7: =INDEX(tb_MHDI[],MATCH(Table3[[#This Row],[city_name]],tb_MHDI[mun_uf],0),8) -> 0.421 | J7: =_xlfn.NUMBERVALUE(INDEX(tb_SVI[],MATCH(Table3[[#This Row],[city_name]],tb_SVI[city_name_uf],0),8),".") -> 0.402 | K7: =_xlfn.NUMBERVALUE(INDEX(tb_SVI[],MATCH(Table3[[#This Row],[city_name]],tb_SVI[city_name_uf],0),9),".") -> 0.2 | L7: =_xlfn.NUMBERVALUE(INDEX(tb_SVI[],MATCH(Table3[[#This Row],[city_name]],tb_SVI[city_name_uf],0),10),".") -> 0.526 | M7: =_xlfn.NUMBERVALUE(INDEX(tb_SVI[],MATCH(Table3[[#This Row],[city_name]],tb_SVI[city_name_uf],0),11),".") -> 0.481 | N7: =_xlfn.PERCENTRANK.INC(Table3[MHDI_tot],Table3[[#This Row],[MHDI_tot]],3) -> 0.18
A8: =SVI!F8 -> Urupá/RO | B8: =INDEX(tb_SVI[],MATCH(Table3[[#This Row],[ibge_cod]],tb_SVI[Município],0),1) -> RO | C8: =INDEX(tb_SVI[],MATCH(Table3[[#This Row],[city_name]],tb_SVI[city_name_uf],0),3) -> 1101708 | D8: BRA.22.48_1 | E8: =INDEX(tb_SVI[],MATCH(Table3[[#This Row],[city_name]],tb_SVI[city_name_uf],0),5) -> 11272 | F8: =INDEX(tb_MHDI[],MATCH(Table3[[#This Row],[city_name]],tb_MHDI[mun_uf],0),5) -> 0.609 | G8: =INDEX(tb_MHDI[],MATCH(Table3[[#This Row],[city_name]],tb_MHDI[mun_uf],0),6) -> 0.621 | H8: =INDEX(tb_MHDI[],MATCH(Table3[[#This Row],[city_name]],tb_MHDI[mun_uf],0),7) -> 0.772 | I8: =INDEX(tb_MHDI[],MATCH(Table3[[#This Row],[city_name]],tb_MHDI[mun_uf],0),8) -> 0.471 | J8: =_xlfn.NUMBERVALUE(INDEX(tb_SVI[],MATCH(Table3[[#This Row],[city_name]],tb_SVI[city_name_uf],0),8),".") -> 0.386 | K8: =_xlfn.NUMBERVALUE(INDEX(tb_SVI[],MATCH(Table3[[#This Row],[city_name]],tb_SVI[city_name_uf],0),9),".") -> 0.194 | L8: =_xlfn.NUMBERVALUE(INDEX(tb_SVI[],MATCH(Table3[[#This Row],[city_name]],tb_SVI[city_name_uf],0),10),".") -> 0.445 | M8: =_xlfn.NUMBERVALUE(INDEX(tb_SVI[],MATCH(Table3[[#This Row],[city_name]],tb_SVI[city_name_uf],0),11),".") -> 0.52 | N8: =_xlfn.PERCENTRANK.INC(Table3[MHDI_tot],Table3[[#This Row],[MHDI_tot]],3) -> 0.289
A9: =SVI!F9 -> Theobroma/RO | B9: =INDEX(tb_SVI[],MATCH(Table3[[#This Row],[ibge_cod]],tb_SVI[Município],0),1) -> RO | C9: =INDEX(tb_SVI[],MATCH(Table3[[#This Row],[city_name]],tb_SVI[city_name_uf],0),3) -> 1101609 | D9: BRA.22.47_1 | E9: =INDEX(tb_SVI[],MATCH(Table3[[#This Row],[city_name]],tb_SVI[city_name_uf],0),5) -> 10395 | F9: =INDEX(tb_MHDI[],MATCH(Table3[[#This Row],[city_name]],tb_MHDI[mun_uf],0),5) -> 0.589 | G9: =INDEX(tb_MHDI[],MATCH(Table3[[#This Row],[city_name]],tb_MHDI[mun_uf],0),6) -> 0.622 | H9: =INDEX(tb_MHDI[],MATCH(Table3[[#This Row],[city_name]],tb_MHDI[mun_uf],0),7) -> 0.757 | I9: =INDEX(tb_MHDI[],MATCH(Table3[[#This Row],[city_name]],tb_MHDI[mun_uf],0),8) -> 0.434 | J9: =_xlfn.NUMBERVALUE(INDEX(tb_SVI[],MATCH(Table3[[#This Row],[city_name]],tb_SVI[city_name_uf],0),8),".") -> 0.352 | K9: =_xlfn.NUMBERVALUE(INDEX(tb_SVI[],MATCH(Table3[[#This Row],[city_name]],tb_SVI[city_name_uf],0),9),".") -> 0.164 | L9: =_xlfn.NUMBERVALUE(INDEX(tb_SVI[],MATCH(Table3[[#This Row],[city_name]],tb_SVI[city_name_uf],0),10),".") -> 0.388 | M9: =_xlfn.NUMBERVALUE(INDEX(tb_SVI[],MATCH(Table3[[#This Row],[city_name]],tb_SVI[city_name_uf],0),11),".") -> 0.505 | N9: =_xlfn.PERCENTRANK.INC(Table3[MHDI_tot],Table3[[#This Row],[MHDI_tot]],3) -> 0.201
A10: =SVI!F10 -> Teixeirópolis/RO | B10: =INDEX(tb_SVI[],MATCH(Table3[[#This Row],[ibge_cod]],tb_SVI[Município],0),1) -> RO | C10: =INDEX(tb_SVI[],MATCH(Table3[[#This Row],[city_name]],tb_SVI[city_name_uf],0),3) -> 1101559 | D10: BRA.22.46_1 | E10: =INDEX(tb_SVI[],MATCH(Table3[[#This Row],[city_name]],tb_SVI[city_name_uf],0),5) -> 4233 | F10: =INDEX(tb_MHDI[],MATCH(Table3[[#This Row],[city_name]],tb_MHDI[mun_uf],0),5) -> 0.643 | G10: =INDEX(tb_MHDI[],MATCH(Table3[[#This Row],[city_name]],tb_MHDI[mun_uf],0),6) -> 0.653 | H10: =INDEX(tb_MHDI[],MATCH(Table3[[#This Row],[city_name]],tb_MHDI[mun_uf],0),7) -> 0.818 | I10: =INDEX(tb_MHDI[],MATCH(Table3[[#This Row],[city_name]],tb_MHDI[mun_uf],0),8) -> 0.498 | J10: =_xlfn.NUMBERVALUE(INDEX(tb_SVI[],MATCH(Table3[[#This Row],[city_name]],tb_SVI[city_name_uf],0),8),".") -> 0.299 | K10: =_xlfn.NUMBERVALUE(INDEX(tb_SVI[],MATCH(Table3[[#This Row],[city_name]],tb_SVI[city_name_uf],0),9),".") -> 0.197 | L10: =_xlfn.NUMBERVALUE(INDEX(tb_SVI[],MATCH(Table3[[#This Row],[city_name]],tb_SVI[city_name_uf],0),10),".") -> 0.322 | M10: =_xlfn.NUMBERVALUE(INDEX(tb_SVI[],MATCH(Table3[[#This Row],[city_name]],tb_SVI[city_name_uf],0),11),".") -> 0.377 | N10: =_xlfn.PERCENTRANK.INC(Table3[MHDI_tot],Table3[[#This Row],[MHDI_tot]],3) -> 0.415
A11: =SVI!F11 -> São Miguel do Guaporé/RO | B11: =INDEX(tb_SVI[],MATCH(Table3[[#This Row],[ibge_cod]],tb_SVI[Município],0),1) -> RO | C11: =INDEX(tb_SVI[],MATCH(Table3[[#This Row],[city_name]],tb_SVI[city_name_uf],0),3) -> 1100320 | D11: BRA.22.44_1 | E11: =INDEX(tb_SVI[],MATCH(Table3[[#This Row],[city_name]],tb_SVI[city_name_uf],0),5) -> 23077 | F11: =INDEX(tb_MHDI[],MATCH(Table3[[#This Row],[city_name]],tb_MHDI[mun_uf],0),5) -> 0.646 | G11: =INDEX(tb_MHDI[],MATCH(Table3[[#This Row],[city_name]],tb_MHDI[mun_uf],0),6) -> 0.644 | H11: =INDEX(tb_MHDI[],MATCH(Table3[[#This Row],[city_name]],tb_MHDI[mun_uf],0),7) -> 0.781 | I11: =INDEX(tb_MHDI[],MATCH(Table3[[#This Row],[city_name]],tb_MHDI[mun_uf],0),8) -> 0.537 | J11: =_xlfn.NUMBERVALUE(INDEX(tb_SVI[],MATCH(Table3[[#This Row],[city_name]],tb_SVI[city_name_uf],0),8),".") -> 0.338 | K11: =_xlfn.NUMBERVALUE(INDEX(tb_SVI[],MATCH(Table3[[#This Row],[city_name]],tb_SVI[city_name_uf],0),9),".") -> 0.127 | L11: =_xlfn.NUMBERVALUE(INDEX(tb_SVI[],MATCH(Table3[[#This Row],[city_name]],tb_SVI[city_name_uf],0),10),".") -> 0.466 | M11: =_xlfn.NUMBERVALUE(INDEX(tb_SVI[],MATCH(Table3[[#This Row],[city_name]],tb_SVI[city_name_uf],0),11),".") -> 0.421 | N11: =_xlfn.PERCENTRANK.INC(Table3[MHDI_tot],Table3[[#This Row],[MHDI_tot]],3) -> 0.425
A12: =SVI!F12 -> São Francisco do Guaporé/RO | B12: =INDEX(tb_SVI[],MATCH(Table3[[#This Row],[ibge_cod]],tb_SVI[Município],0),1) -> RO | C12: =INDEX(tb_SVI[],MATCH(Table3[[#This Row],[city_name]],tb_SVI[city_name_uf],0),3) -> 1101492 | D12: BRA.22.43_1 | E12: =INDEX(tb_SVI[],MATCH(Table3[[#This Row],[city_name]],tb_SVI[city_name_uf],0),5) -> 20681 | F12: =INDEX(tb_MHDI[],MATCH(Table3[[#This Row],[city_name]],tb_MHDI[mun_uf],0),5) -> 0.611 | G12: =INDEX(tb_MHDI[],MATCH(Table3[[#This Row],[city_name]],tb_MHDI[mun_uf],0),6) -> 0.657 | H12: =INDEX(tb_MHDI[],MATCH(Table3[[#This Row],[city_name]],tb_MHDI[mun_uf],0),7) -> 0.751 | I12: =INDEX(tb_MHDI[],MATCH(Table3[[#This Row],[city_name]],tb_MHDI[mun_uf],0),8) -> 0.462 | J12: =_xlfn.NUMBERVALUE(INDEX(tb_SVI[],MATCH(Table3[[#This Row],[city_name]],tb_SVI[city_name_uf],0),8),".") -> 0.429 | K12: =_xlfn.NUMBERVALUE(INDEX(tb_SVI[],MATCH(Table3[[#This Row],[city_name]],tb_SVI[city_name_uf],0),9),".") -> 0.282 | L12: =_xlfn.NUMBERVALUE(INDEX(tb_SVI[],MATCH(Table3[[#This Row],[city_name]],tb_SVI[city_name_uf],0),10),".") -> 0.554 | M12: =_xlfn.NUMBERVALUE(INDEX(tb_SVI[],MATCH(Table3[[#This Row],[city_name]],tb_SVI[city_name_uf],0),11),".") -> 0.451 | N12: =_xlfn.PERCENTRANK.INC(Table3[MHDI_tot],Table3[[#This Row],[MHDI_tot]],3) -> 0.299
A13: =SVI!F13 -> São Felipe D'Oeste/RO | B13: =INDEX(tb_SVI[],MATCH(Table3[[#This Row],[ibge_cod]],tb_SVI[Município],0),1) -> RO | C13: =INDEX(tb_SVI[],MATCH(Table3[[#This Row],[city_name]],tb_SVI[city_name_uf],0),3) -> 1101484 | D13: BRA.22.42_1 | E13: =INDEX(tb_SVI[],MATCH(Table3[[#This Row],[city_name]],tb_SVI[city_name_uf],0),5) -> 5066 | F13: =INDEX(tb_MHDI[],MATCH(Table3[[#This Row],[city_name]],tb_MHDI[mun_uf],0),5) -> 0.649 | G13: =INDEX(tb_MHDI[],MATCH(Table3[[#This Row],[city_name]],tb_MHDI[mun_uf],0),6) -> 0.615 | H13: =INDEX(tb_MHDI[],MATCH(Table3[[#This Row],[city_name]],tb_MHDI[mun_uf],0),7) -> 0.78 | I13: =INDEX(tb_MHDI[],MATCH(Table3[[#This Row],[city_name]],tb_MHDI[mun_uf],0),8) -> 0.571 | J13: =_xlfn.NUMBERVALUE(INDEX(tb_SVI[],MATCH(Table3[[#This Row],[city_name]],tb_SVI[city_name_uf],0),8),".") -> 0.338 | K13: =_xlfn.NUMBERVALUE(INDEX(tb_SVI[],MATCH(Table3[[#This Row],[city_name]],tb_SVI[city_name_uf],0),9),".") -> 0.159 | L13: =_xlfn.NUMBERVALUE(INDEX(tb_SVI[],MATCH(Table3[[#This Row],[city_name]],tb_SVI[city_name_uf],0),10),".") -> 0.447 | M13: =_xlfn.NUMBERVALUE(INDEX(tb_SVI[],MATCH(Table3[[#This Row],[city_name]],tb_SVI[city_name_uf],0),11),".") -> 0.407 | N13: =_xlfn.PERCENTRANK.INC(Table3[MHDI_tot],Table3[[#This Row],[MHDI_tot]],3) -> 0.433
A14: =SVI!F14 -> Seringueiras/RO | B14: =INDEX(tb_SVI[],MATCH(Table3[[#This Row],[ibge_cod]],tb_SVI[Município],0),1) -> RO | C14: =INDEX(tb_SVI[],MATCH(Table3[[#This Row],[city_name]],tb_SVI[city_name_uf],0),3) -> 1101500 | D14: BRA.22.45_1 | E14: =INDEX(tb_SVI[],MATCH(Table3[[#This Row],[city_name]],tb_SVI[city_name_uf],0),5) -> 11851 | F14: =INDEX(tb_MHDI[],MATCH(Table3[[#This Row],[city_name]],tb_MHDI[mun_uf],0),5) -> 0.598 | G14: =INDEX(tb_MHDI[],MATCH(Table3[[#This Row],[city_name]],tb_MHDI[mun_uf],0),6) -> 0.644 | H14: =INDEX(tb_MHDI[],MATCH(Table3[[#This Row],[city_name]],tb_MHDI[mun_uf],0),7) -> 0.779 | I14: =INDEX(tb_MHDI[],MATCH(Table3[[#This Row],[city_name]],tb_MHDI[mun_uf],0),8) -> 0.427 | J14: =_xlfn.NUMBERVALUE(INDEX(tb_SVI[],MATCH(Table3[[#This Row],[city_name]],tb_SVI[city_name_uf],0),8),".") -> 0.401 | K14: =_xlfn.NUMBERVALUE(INDEX(tb_SVI[],MATCH(Table3[[#This Row],[city_name]],tb_SVI[city_name_uf],0),9),".") -> 0.194 | L14: =_xlfn.NUMBERVALUE(INDEX(tb_SVI[],MATCH(Table3[[#This Row],[city_name]],tb_SVI[city_name_uf],0),10),".") -> 0.447 | M14: =_xlfn.NUMBERVALUE(INDEX(tb_SVI[],MATCH(Table3[[#This Row],[city_name]],tb_SVI[city_name_uf],0),11),".") -> 0.563 | N14: =_xlfn.PERCENTRANK.INC(Table3[MHDI_tot],Table3[[#This Row],[MHDI_tot]],3) -> 0.242
A15: =SVI!F15 -> Santa Luzia D'Oeste/RO | B15: =INDEX(tb_SVI[],MATCH(Table3[[#This Row],[ibge_cod]],tb_SVI[Município],0),1) -> RO | C15: =INDEX(tb_SVI[],MATCH(Table3[[#This Row],[city_name]],tb_SVI[city_name_uf],0),3) -> 1100296 | D15: BRA.22.41_1 | E15: =INDEX(tb_SVI[],MATCH(Table3[[#This Row],[city_name]],tb_SVI[city_name_uf],0),5) -> 6216 | F15: =INDEX(tb_MHDI[],MATCH(Table3[[#This Row],[city_name]],tb_MHDI[mun_uf],0),5) -> 0.67 | G15: =INDEX(tb_MHDI[],MATCH(Table3[[#This Row],[city_name]],tb_MHDI[mun_uf],0),6) -> 0.657 | H15: =INDEX(tb_MHDI[],MATCH(Table3[[#This Row],[city_name]],tb_MHDI[mun_uf],0),7) -> 0.812 | I15: =INDEX(tb_MHDI[],MATCH(Table3[[#This Row],[city_name]],tb_MHDI[mun_uf],0),8) -> 0.564 | J15: =_xlfn.NUMBERVALUE(INDEX(tb_SVI[],MATCH(Table3[[#This Row],[city_name]],tb_SVI[city_name_uf],0),8),".") -> 0.364 | K15: =_xlfn.NUMBERVALUE(INDEX(tb_SVI[],MATCH(Table3[[#This Row],[city_name]],tb_SVI[city_name_uf],0),9),".") -> 0.254 | L15: =_xlfn.NUMBERVALUE(INDEX(tb_SVI[],MATCH(Table3[[#This Row],[city_name]],tb_SVI[city_name_uf],0),10),".") -> 0.375 | M15: =_xlfn.NUMBERVALUE(INDEX(tb_SVI[],MATCH(Table3[[#This Row],[city_name]],tb_SVI[city_name_uf],0),11),".") -> 0.463 | N15: =_xlfn.PERCENTRANK.INC(Table3[MHDI_tot],Table3[[#This Row],[MHDI_tot]],3) -> 0.516
A16: =SVI!F16 -> Rolim de Moura/RO | B16: =INDEX(tb_SVI[],MATCH(Table3[[#This Row],[ibge_cod]],tb_SVI[Município],0),1) -> RO | C16: =INDEX(tb_SVI[],MATCH(Table3[[#This Row],[city_name]],tb_SVI[city_name_uf],0),3) -> 1100288 | D16: BRA.22.40_1 | E16: =INDEX(tb_SVI[],MATCH(Table3[[#This Row],[city_name]],tb_SVI[city_name_uf],0),5) -> 55407 | F16: =INDEX(tb_MHDI[],MATCH(Table3[[#This Row],[city_name]],tb_MHDI[mun_uf],0),5) -> 0.7 | G16: =INDEX(tb_MHDI[],MATCH(Table3[[#This Row],[city_name]],tb_MHDI[mun_uf],0),6) -> 0.709 | H16: =INDEX(tb_MHDI[],MATCH(Table3[[#This Row],[city_name]],tb_MHDI[mun_uf],0),7) -> 0.808 | I16: =INDEX(tb_MHDI[],MATCH(Table3[[#This Row],[city_name]],tb_MHDI[mun_uf],0),8) -> 0.598 | J16: =_xlfn.NUMBERVALUE(INDEX(tb_SVI[],MATCH(Table3[[#This Row],[city_name]],tb_SVI[city_name_uf],0),8),".") -> 0.264 | K16: =_xlfn.NUMBERVALUE(INDEX(tb_SVI[],MATCH(Table3[[#This Row],[city_name]],tb_SVI[city_name_uf],0),9),".") -> 0.101 | L16: =_xlfn.NUMBERVALUE(INDEX(tb_SVI[],MATCH(Table3[[#This Row],[city_name]],tb_SVI[city_name_uf],0),10),".") -> 0.384 | M16: =_xlfn.NUMBERVALUE(INDEX(tb_SVI[],MATCH(Table3[[#This Row],[city_name]],tb_SVI[city_name_uf],0),11),".") -> 0.308 | N16: =_xlfn.PERCENTRANK.INC(Table3[MHDI_tot],Table3[[#This Row],[MHDI_tot]],3) -> 0.652
A17: =SVI!F17 -> Rio Crespo/RO | B17: =INDEX(tb_SVI[],MATCH(Table3[[#This Row],[ibge_cod]],tb_SVI[Município],0),1) -> RO | C17: =INDEX(tb_SVI[],MATCH(Table3[[#This Row],[city_name]],tb_SVI[city_name_uf],0),3) -> 1100262 | D17: BRA.22.39_1 | E17: =INDEX(tb_SVI[],MATCH(Table3[[#This Row],[city_name]],tb_SVI[city_name_uf],0),5) -> 3804 | F17: =INDEX(tb_MHDI[],MATCH(Table3[[#This Row],[city_name]],tb_MHDI[mun_uf],0),5) -> 0.643 | G17: =INDEX(tb_MHDI[],MATCH(Table3[[#This Row],[city_name]],tb_MHDI[mun_uf],0),6) -> 0.637 | H17: =INDEX(tb_MHDI[],MATCH(Table3[[#This Row],[city_name]],tb_MHDI[mun_uf],0),7) -> 0.813 | I17: =INDEX(tb_MHDI[],MATCH(Table3[[#This Row],[city_name]],tb_MHDI[mun_uf],0),8) -> 0.513 | J17: =_xlfn.NUMBERVALUE(INDEX(tb_SVI[],MATCH(Table3[[#This Row],[city_name]],tb_SVI[city_name_uf],0),8),".") -> 0.348 | K17: =_xlfn.NUMBERVALUE(INDEX(tb_SVI[],MATCH(Table3[[#This Row],[city_name]],tb_SVI[city_name_uf],0),9),".") -> 0.169 | L17: =_xlfn.NUMBERVALUE(INDEX(tb_SVI[],MATCH(Table3[[#This Row],[city_name]],tb_SVI[city_name_uf],0),10),".") -> 0.459 | M17: =_xlfn.NUMBERVALUE(INDEX(tb_SVI[],MATCH(Table3[[#This Row],[city_name]],tb_SVI[city_name_uf],0),11),".") -> 0.415 | N17: =_xlfn.PERCENTRANK.INC(Table3[MHDI_tot],Table3[[#This Row],[MHDI_tot]],3) -> 0.415
A18: =SVI!F18 -> Primavera de Rondônia/RO | B18: =INDEX(tb_SVI[],MATCH(Table3[[#This Row],[ibge_cod]],tb_SVI[Município],0),1) -> RO | C18: =INDEX(tb_SVI[],MATCH(Table3[[#This Row],[city_name]],tb_SVI[city_name_uf],0),3) -> 1101476 | D18: BRA.22.38_1 | E18: =INDEX(tb_SVI[],MATCH(Table3[[#This Row],[city_name]],tb_SVI[city_name_uf],0),5) -> 2776 | F18: =INDEX(tb_MHDI[],MATCH(Table3[[#This Row],[city_name]],tb_MHDI[mun_uf],0),5) -> 0.641 | G18: =INDEX(tb_MHDI[],MATCH(Table3[[#This Row],[city_name]],tb_MHDI[mun_uf],0),6) -> 0.645 | H18: =INDEX(tb_MHDI[],MATCH(Table3[[#This Row],[city_name]],tb_MHDI[mun_uf],0),7) -> 0.799 | I18: =INDEX(tb_MHDI[],MATCH(Table3[[#This Row],[city_name]],tb_MHDI[mun_uf],0),8) -> 0.512 | J18: =_xlfn.NUMBERVALUE(INDEX(tb_SVI[],MATCH(Table3[[#This Row],[city_name]],tb_SVI[city_name_uf],0),8),".") -> 0.298 | K18: =_xlfn.NUMBERVALUE(INDEX(tb_SVI[],MATCH(Table3[[#This Row],[city_name]],tb_SVI[city_name_uf],0),9),".") -> 0.067 | L18: =_xlfn.NUMBERVALUE(INDEX(tb_SVI[],MATCH(Table3[[#This Row],[city_name]],tb_SVI[city_name_uf],0),10),".") -> 0.364 | M18: =_xlfn.NUMBERVALUE(INDEX(tb_SVI[],MATCH(Table3[[#This Row],[city_name]],tb_SVI[city_name_uf],0),11),".") -> 0.463 | N18: =_xlfn.PERCENTRANK.INC(Table3[MHDI_tot],Table3[[#This Row],[MHDI_tot]],3) -> 0.408
... A44: =SVI!F44 -> Campo Novo de Rondônia/RO | B44: =INDEX(tb_SVI[],MATCH(Table3[[#This Row],[ibge_cod]],tb_SVI[Município],0),1) -> RO | C44: =INDEX(tb_SVI[],MATCH(Table3[[#This Row],[city_name]],tb_SVI[city_name_uf],0),3) -> 1100700 | D44: BRA.22.9_1 | E44: =INDEX(tb_SVI[],MATCH(Table3[[#This Row],[city_name]],tb_SVI[city_name_uf],0),5) -> 14266 | F44: =INDEX(tb_MHDI[],MATCH(Table3[[#This Row],[city_name]],tb_MHDI[mun_uf],0),5) -> 0.593 | G44: =INDEX(tb_MHDI[],MATCH(Table3[[#This Row],[city_name]],tb_MHDI[mun_uf],0),6) -> 0.667 | H44: =INDEX(tb_MHDI[],MATCH(Table3[[#This Row],[city_name]],tb_MHDI[mun_uf],0),7) -> 0.772 | I44: =INDEX(tb_MHDI[],MATCH(Table3[[#This Row],[city_name]],tb_MHDI[mun_uf],0),8) -> 0.404 | J44: =_xlfn.NUMBERVALUE(INDEX(tb_SVI[],MATCH(Table3[[#This Row],[city_name]],tb_SVI[city_name_uf],0),8),".") -> 0.482 | K44: =_xlfn.NUMBERVALUE(INDEX(tb_SVI[],MATCH(Table3[[#This Row],[city_name]],tb_SVI[city_name_uf],0),9),".") -> 0.407 | L44: =_xlfn.NUMBERVALUE(INDEX(tb_SVI[],MATCH(Table3[[#This Row],[city_name]],tb_SVI[city_name_uf],0),10),".") -> 0.622 | M44: =_xlfn.NUMBERVALUE(INDEX(tb_SVI[],MATCH(Table3[[#This Row],[city_name]],tb_SVI[city_name_uf],0),11),".") -> 0.417 | N44: =_xlfn.PERCENTRANK.INC(Table3[MHDI_tot],Table3[[#This Row],[MHDI_tot]],3) -> 0.221
A45: =SVI!F67 -> Jordão/AC | B45: =INDEX(tb_SVI[],MATCH(Table3[[#This Row],[ibge_cod]],tb_SVI[Município],0),1) -> AC | C45: =INDEX(tb_SVI[],MATCH(Table3[[#This Row],[city_name]],tb_SVI[city_name_uf],0),3) -> 1200328 | D45: BRA.1.9_1 | E45: =INDEX(tb_SVI[],MATCH(Table3[[#This Row],[city_name]],tb_SVI[city_name_uf],0),5) -> 8473 | F45: =INDEX(tb_MHDI[],MATCH(Table3[[#This Row],[city_name]],tb_MHDI[mun_uf],0),5) -> 0.469 | G45: =INDEX(tb_MHDI[],MATCH(Table3[[#This Row],[city_name]],tb_MHDI[mun_uf],0),6) -> 0.499 | H45: =INDEX(tb_MHDI[],MATCH(Table3[[#This Row],[city_name]],tb_MHDI[mun_uf],0),7) -> 0.731 | I45: =INDEX(tb_MHDI[],MATCH(Table3[[#This Row],[city_name]],tb_MHDI[mun_uf],0),8) -> 0.283 | J45: =_xlfn.NUMBERVALUE(INDEX(tb_SVI[],MATCH(Table3[[#This Row],[city_name]],tb_SVI[city_name_uf],0),8),".") -> 0.584 | K45: =_xlfn.NUMBERVALUE(INDEX(tb_SVI[],MATCH(Table3[[#This Row],[city_name]],tb_SVI[city_name_uf],0),9),".") -> 0.437 | L45: =_xlfn.NUMBERVALUE(INDEX(tb_SVI[],MATCH(Table3[[#This Row],[city_name]],tb_SVI[city_name_uf],0),10),".") -> 0.779 | M45: =_xlfn.NUMBERVALUE(INDEX(tb_SVI[],MATCH(Table3[[#This Row],[city_name]],tb_SVI[city_name_uf],0),11),".") -> 0.535 | N45: =_xlfn.PERCENTRANK.INC(Table3[MHDI_tot],Table3[[#This Row],[MHDI_tot]],3) -> 0.001
A46: =SVI!F46 -> Cacaulândia/RO | B46: =INDEX(tb_SVI[],MATCH(Table3[[#This Row],[ibge_cod]],tb_SVI[Município],0),1) -> RO | C46: =INDEX(tb_SVI[],MATCH(Table3[[#This Row],[city_name]],tb_SVI[city_name_uf],0),3) -> 1100601 | D46: BRA.22.7_1 | E46: =INDEX(tb_SVI[],MATCH(Table3[[#This Row],[city_name]],tb_SVI[city_name_uf],0),5) -> 6269 | F46: =INDEX(tb_MHDI[],MATCH(Table3[[#This Row],[city_name]],tb_MHDI[mun_uf],0),5) -> 0.646 | G46: =INDEX(tb_MHDI[],MATCH(Table3[[#This Row],[city_name]],tb_MHDI[mun_uf],0),6) -> 0.664 | H46: =INDEX(tb_MHDI[],MATCH(Table3[[#This Row],[city_name]],tb_MHDI[mun_uf],0),7) -> 0.801 | I46: =INDEX(tb_MHDI[],MATCH(Table3[[#This Row],[city_name]],tb_MHDI[mun_uf],0),8) -> 0.506 | J46: =_xlfn.NUMBERVALUE(INDEX(tb_SVI[],MATCH(Table3[[#This Row],[city_name]],tb_SVI[city_name_uf],0),8),".") -> 0.335 | K46: =_xlfn.NUMBERVALUE(INDEX(tb_SVI[],MATCH(Table3[[#This Row],[city_name]],tb_SVI[city_name_uf],0),9),".") -> 0.131 | L46: =_xlfn.NUMBERVALUE(INDEX(tb_SVI[],MATCH(Table3[[#This Row],[city_name]],tb_SVI[city_name_uf],0),10),".") -> 0.47 | M46: =_xlfn.NUMBERVALUE(INDEX(tb_SVI[],MATCH(Table3[[#This Row],[city_name]],tb_SVI[city_name_uf],0),11),".") -> 0.405 | N46: =_xlfn.PERCENTRANK.INC(Table3[MHDI_tot],Table3[[#This Row],[MHDI_tot]],3) -> 0.425
A47: =SVI!F47 -> Cabixi/RO | B47: =INDEX(tb_SVI[],MATCH(Table3[[#This Row],[ibge_cod]],tb_SVI[Município],0),1) -> RO | C47: =INDEX(tb_SVI[],MATCH(Table3[[#This Row],[city_name]],tb_SVI[city_name_uf],0),3) -> 1100031 | D47: BRA.12.19_1 | E47: =INDEX(tb_SVI[],MATCH(Table3[[#This Row],[city_name]],tb_SVI[city_name_uf],0),5) -> 5188 | F47: =INDEX(tb_MHDI[],MATCH(Table3[[#This Row],[city_name]],tb_MHDI[mun_uf],0),5) -> 0.65 | G47: =INDEX(tb_MHDI[],MATCH(Table3[[#This Row],[city_name]],tb_MHDI[mun_uf],0),6) -> 0.65 | H47: =INDEX(tb_MHDI[],MATCH(Table3[[#This Row],[city_name]],tb_MHDI[mun_uf],0),7) -> 0.757 | I47: =INDEX(tb_MHDI[],MATCH(Table3[[#This Row],[city_name]],tb_MHDI[mun_uf],0),8) -> 0.559 | J47: =_xlfn.NUMBERVALUE(INDEX(tb_SVI[],MATCH(Table3[[#This Row],[city_name]],tb_SVI[city_name_uf],0),8),".") -> 0.3 | K47: =_xlfn.NUMBERVALUE(INDEX(tb_SVI[],MATCH(Table3[[#This Row],[city_name]],tb_SVI[city_name_uf],0),9),".") -> 0.128 | L47: =_xlfn.NUMBERVALUE(INDEX(tb_SVI[],MATCH(Table3[[#This Row],[city_name]],tb_SVI[city_name_uf],0),10),".") -> 0.389 | M47: =_xlfn.NUMBERVALUE(INDEX(tb_SVI[],MATCH(Table3[[#This Row],[city_name]],tb_SVI[city_name_uf],0),11),".") -> 0.383 | N47: =_xlfn.PERCENTRANK.INC(Table3[MHDI_tot],Table3[[#This Row],[MHDI_tot]],3) -> 0.436
A48: =SVI!F48 -> Buritis/RO | B48: =INDEX(tb_SVI[],MATCH(Table3[[#This Row],[ibge_cod]],tb_SVI[Município],0),1) -> RO | C48: =INDEX(tb_SVI[],MATCH(Table3[[#This Row],[city_name]],tb_SVI[city_name_uf],0),3) -> 1100452 | D48: BRA.22.6_1 | E48: =INDEX(tb_SVI[],MATCH(Table3[[#This Row],[city_name]],tb_SVI[city_name_uf],0),5) -> 40356 | F48: =INDEX(tb_MHDI[],MATCH(Table3[[#This Row],[city_name]],tb_MHDI[mun_uf],0),5) -> 0.616 | G48: =INDEX(tb_MHDI[],MATCH(Table3[[#This Row],[city_name]],tb_MHDI[mun_uf],0),6) -> 0.65 | H48: =INDEX(tb_MHDI[],MATCH(Table3[[#This Row],[city_name]],tb_MHDI[mun_uf],0),7) -> 0.751 | I48: =INDEX(tb_MHDI[],MATCH(Table3[[#This Row],[city_name]],tb_MHDI[mun_uf],0),8) -> 0.479 | J48: =_xlfn.NUMBERVALUE(INDEX(tb_SVI[],MATCH(Table3[[#This Row],[city_name]],tb_SVI[city_name_uf],0),8),".") -> 0.38 | K48: =_xlfn.NUMBERVALUE(INDEX(tb_SVI[],MATCH(Table3[[#This Row],[city_name]],tb_SVI[city_name_uf],0),9),".") -> 0.191 | L48: =_xlfn.NUMBERVALUE(INDEX(tb_SVI[],MATCH(Table3[[#This Row],[city_name]],tb_SVI[city_name_uf],0),10),".") -> 0.487 | M48: =_xlfn.NUMBERVALUE(INDEX(tb_SVI[],MATCH(Table3[[#This Row],[city_name]],tb_SVI[city_name_uf],0),11),".") -> 0.462 | N48: =_xlfn.PERCENTRANK.INC(Table3[MHDI_tot],Table3[[#This Row],[MHDI_tot]],3) -> 0.318
A49: =SVI!F49 -> Ariquemes/RO | B49: =INDEX(tb_SVI[],MATCH(Table3[[#This Row],[ibge_cod]],tb_SVI[Município],0),1) -> RO | C49: =INDEX(tb_SVI[],MATCH(Table3[[#This Row],[city_name]],tb_SVI[city_name_uf],0),3) -> 1100023 | D49: BRA.22.5_1 | E49: =INDEX(tb_SVI[],MATCH(Table3[[#This Row],[city_name]],tb_SVI[city_name_uf],0),5) -> 109523 | F49: =INDEX(tb_MHDI[],MATCH(Table3[[#This Row],[city_name]],tb_MHDI[mun_uf],0),5) -> 0.702 | G49: =INDEX(tb_MHDI[],MATCH(Table3[[#This Row],[city_name]],tb_MHDI[mun_uf],0),6) -> 0.716 | H49: =INDEX(tb_MHDI[],MATCH(Table3[[#This Row],[city_name]],tb_MHDI[mun_uf],0),7) -> 0.806 | I49: =INDEX(tb_MHDI[],MATCH(Table3[[#This Row],[city_name]],tb_MHDI[mun_uf],0),8) -> 0.6 | J49: =_xlfn.NUMBERVALUE(INDEX(tb_SVI[],MATCH(Table3[[#This Row],[city_name]],tb_SVI[city_name_uf],0),8),".") -> 0.268 | K49: =_xlfn.NUMBERVALUE(INDEX(tb_SVI[],MATCH(Table3[[#This Row],[city_name]],tb_SVI[city_name_uf],0),9),".") -> 0.149 | L49: =_xlfn.NUMBERVALUE(INDEX(tb_SVI[],MATCH(Table3[[#This Row],[city_name]],tb_SVI[city_name_uf],0),10),".") -> 0.384 | M49: =_xlfn.NUMBERVALUE(INDEX(tb_SVI[],MATCH(Table3[[#This Row],[city_name]],tb_SVI[city_name_uf],0),11),".") -> 0.271 | N49: =_xlfn.PERCENTRANK.INC(Table3[MHDI_tot],Table3[[#This Row],[MHDI_tot]],3) -> 0.664
A50: =SVI!F50 -> Alvorada D'Oeste/RO | B50: =INDEX(tb_SVI[],MATCH(Table3[[#This Row],[ibge_cod]],tb_SVI[Município],0),1) -> RO | C50: =INDEX(tb_SVI[],MATCH(Table3[[#This Row],[city_name]],tb_SVI[city_name_uf],0),3) -> 1100346 | D50: BRA.22.4_1 | E50: =INDEX(tb_SVI[],MATCH(Table3[[#This Row],[city_name]],tb_SVI[city_name_uf],0),5) -> 14106 | F50: =INDEX(tb_MHDI[],MATCH(Table3[[#This Row],[city_name]],tb_MHDI[mun_uf],0),5) -> 0.643 | G50: =INDEX(tb_MHDI[],MATCH(Table3[[#This Row],[city_name]],tb_MHDI[mun_uf],0),6) -> 0.654 | H50: =INDEX(tb_MHDI[],MATCH(Table3[[#This Row],[city_name]],tb_MHDI[mun_uf],0),7) -> 0.763 | I50: =INDEX(tb_MHDI[],MATCH(Table3[[#This Row],[city_name]],tb_MHDI[mun_uf],0),8) -> 0.534 | J50: =_xlfn.NUMBERVALUE(INDEX(tb_SVI[],MATCH(Table3[[#This Row],[city_name]],tb_SVI[city_name_uf],0),8),".") -> 0.346 | K50: =_xlfn.NUMBERVALUE(INDEX(tb_SVI[],MATCH(Table3[[#This Row],[city_name]],tb_SVI[city_name_uf],0),9),".") -> 0.232 | L50: =_xlfn.NUMBERVALUE(INDEX(tb_SVI[],MATCH(Table3[[#This Row],[city_name]],tb_SVI[city_name_uf],0),10),".") -> 0.411 | M50: =_xlfn.NUMBERVALUE(INDEX(tb_SVI[],MATCH(Table3[[#This Row],[city_name]],tb_SVI[city_name_uf],0),11),".") -> 0.394 | N50: =_xlfn.PERCENTRANK.INC(Table3[MHDI_tot],Table3[[#This Row],[MHDI_tot]],3) -> 0.415
A51: =SVI!F51 -> Alto Paraíso/RO | B51: =INDEX(tb_SVI[],MATCH(Table3[[#This Row],[ibge_cod]],tb_SVI[Município],0),1) -> RO | C51: =INDEX(tb_SVI[],MATCH(Table3[[#This Row],[city_name]],tb_SVI[city_name_uf],0),3) -> 1100403 | D51: BRA.22.3_1 | E51: =INDEX(tb_SVI[],MATCH(Table3[[#This Row],[city_name]],tb_SVI[city_name_uf],0),5) -> 21847 | F51: =INDEX(tb_MHDI[],MATCH(Table3[[#This Row],[city_name]],tb_MHDI[mun_uf],0),5) -> 0.625 | G51: =INDEX(tb_MHDI[],MATCH(Table3[[#This Row],[city_name]],tb_MHDI[mun_uf],0),6) -> 0.664 | H51: =INDEX(tb_MHDI[],MATCH(Table3[[#This Row],[city_name]],tb_MHDI[mun_uf],0),7) -> 0.804 | I51: =INDEX(tb_MHDI[],MATCH(Table3[[#This Row],[city_name]],tb_MHDI[mun_uf],0),8) -> 0.457 | J51: =_xlfn.NUMBERVALUE(INDEX(tb_SVI[],MATCH(Table3[[#This Row],[city_name]],tb_SVI[city_name_uf],0),8),".") -> 0.372 | K51: =_xlfn.NUMBERVALUE(INDEX(tb_SVI[],MATCH(Table3[[#This Row],[city_name]],tb_SVI[city_name_uf],0),9),".") -> 0.23 | L51: =_xlfn.NUMBERVALUE(INDEX(tb_SVI[],MATCH(Table3[[#This Row],[city_name]],tb_SVI[city_name_uf],0),10),".") -> 0.453 | M51: =_xlfn.NUMBERVALUE(INDEX(tb_SVI[],MATCH(Table3[[#This Row],[city_name]],tb_SVI[city_name_uf],0),11),".") -> 0.432 | N51: =_xlfn.PERCENTRANK.INC(Table3[MHDI_tot],Table3[[#This Row],[MHDI_tot]],3) -> 0.352
A52: =SVI!F52 -> Alto Alegre dos Parecis/RO | B52: =INDEX(tb_SVI[],MATCH(Table3[[#This Row],[ibge_cod]],tb_SVI[Município],0),1) -> RO | C52: =INDEX(tb_SVI[],MATCH(Table3[[#This Row],[city_name]],tb_SVI[city_name_uf],0),3) -> 1100379 | D52: BRA.22.2_1 | E52: =INDEX(tb_SVI[],MATCH(Table3[[#This Row],[city_name]],tb_SVI[city_name_uf],0),5) -> 13255 | F52: =INDEX(tb_MHDI[],MATCH(Table3[[#This Row],[city_name]],tb_MHDI[mun_uf],0),5) -> 0.592 | G52: =INDEX(tb_MHDI[],MATCH(Table3[[#This Row],[city_name]],tb_MHDI[mun_uf],0),6) -> 0.603 | H52: =INDEX(tb_MHDI[],MATCH(Table3[[#This Row],[city_name]],tb_MHDI[mun_uf],0),7) -> 0.777 | I52: =INDEX(tb_MHDI[],MATCH(Table3[[#This Row],[city_name]],tb_MHDI[mun_uf],0),8) -> 0.443 | J52: =_xlfn.NUMBERVALUE(INDEX(tb_SVI[],MATCH(Table3[[#This Row],[city_name]],tb_SVI[city_name_uf],0),8),".") -> 0.418 | K52: =_xlfn.NUMBERVALUE(INDEX(tb_SVI[],MATCH(Table3[[#This Row],[city_name]],tb_SVI[city_name_uf],0),9),".") -> 0.24 | L52: =_xlfn.NUMBERVALUE(INDEX(tb_SVI[],MATCH(Table3[[#This Row],[city_name]],tb_SVI[city_name_uf],0),10),".") -> 0.477 | M52: =_xlfn.NUMBERVALUE(INDEX(tb_SVI[],MATCH(Table3[[#This Row],[city_name]],tb_SVI[city_name_uf],0),11),".") -> 0.537 | N52: =_xlfn.PERCENTRANK.INC(Table3[MHDI_tot],Table3[[#This Row],[MHDI_tot]],3) -> 0.214
A53: =SVI!F53 -> Alta Floresta D'Oeste/RO | B53: =INDEX(tb_SVI[],MATCH(Table3[[#This Row],[ibge_cod]],tb_SVI[Município],0),1) -> RO | C53: =INDEX(tb_SVI[],MATCH(Table3[[#This Row],[city_name]],tb_SVI[city_name_uf],0),3) -> 1100015 | D53: BRA.22.1_1 | E53: =INDEX(tb_SVI[],MATCH(Table3[[#This Row],[city_name]],tb_SVI[city_name_uf],0),5) -> 22728 | F53: =INDEX(tb_MHDI[],MATCH(Table3[[#This Row],[city_name]],tb_MHDI[mun_uf],0),5) -> 0.641 | G53: =INDEX(tb_MHDI[],MATCH(Table3[[#This Row],[city_name]],tb_MHDI[mun_uf],0),6) -> 0.657 | H53: =INDEX(tb_MHDI[],MATCH(Table3[[#This Row],[city_name]],tb_MHDI[mun_uf],0),7) -> 0.763 | I53: =INDEX(tb_MHDI[],MATCH(Table3[[#This Row],[city_name]],tb_MHDI[mun_uf],0),8) -> 0.526 | J53: =_xlfn.NUMBERVALUE(INDEX(tb_SVI[],MATCH(Table3[[#This Row],[city_name]],tb_SVI[city_name_uf],0),8),".") -> 0.376 | K53: =_xlfn.NUMBERVALUE(INDEX(tb_SVI[],MATCH(Table3[[#This Row],[city_name]],tb_SVI[city_name_uf],0),9),".") -> 0.306 | L53: =_xlfn.NUMBERVALUE(INDEX(tb_SVI[],MATCH(Table3[[#This Row],[city_name]],tb_SVI[city_name_uf],0),10),".") -> 0.45 | M53: =_xlfn.NUMBERVALUE(INDEX(tb_SVI[],MATCH(Table3[[#This Row],[city_name]],tb_SVI[city_name_uf],0),11),".") -> 0.373 | N53: =_xlfn.PERCENTRANK.INC(Table3[MHDI_tot],Table3[[#This Row],[MHDI_tot]],3) -> 0.408
A54: =SVI!F54 -> Xapuri/AC | B54: =INDEX(tb_SVI[],MATCH(Table3[[#This Row],[ibge_cod]],tb_SVI[Município],0),1) -> AC | C54: =INDEX(tb_SVI[],MATCH(Table3[[#This Row],[city_name]],tb_SVI[city_name_uf],0),3) -> 1200708 | D54: BRA.1.22_1 | E54: =INDEX(tb_SVI[],MATCH(Table3[[#This Row],[city_name]],tb_SVI[city_name_uf],0),5) -> 19596 | F54: =INDEX(tb_MHDI[],MATCH(Table3[[#This Row],[city_name]],tb_MHDI[mun_uf],0),5) -> 0.599 | G54: =INDEX(tb_MHDI[],MATCH(Table3[[#This Row],[city_name]],tb_MHDI[mun_uf],0),6) -> 0.621 | H54: =INDEX(tb_MHDI[],MATCH(Table3[[#This Row],[city_name]],tb_MHDI[mun_uf],0),7) -> 0.773 | I54: =INDEX(tb_MHDI[],MATCH(Table3[[#This Row],[city_name]],tb_MHDI[mun_uf],0),8) -> 0.448 | J54: =_xlfn.NUMBERVALUE(INDEX(tb_SVI[],MATCH(Table3[[#This Row],[city_name]],tb_SVI[city_name_uf],0),8),".") -> 0.49 | K54: =_xlfn.NUMBERVALUE(INDEX(tb_SVI[],MATCH(Table3[[#This Row],[city_name]],tb_SVI[city_name_uf],0),9),".") -> 0.341 | L54: =_xlfn.NUMBERVALUE(INDEX(tb_SVI[],MATCH(Table3[[#This Row],[city_name]],tb_SVI[city_name_uf],0),10),".") -> 0.661 | M54: =_xlfn.NUMBERVALUE(INDEX(tb_SVI[],MATCH(Table3[[#This Row],[city_name]],tb_SVI[city_name_uf],0),11),".") -> 0.468 | N54: =_xlfn.PERCENTRANK.INC(Table3[MHDI_tot],Table3[[#This Row],[MHDI_tot]],3) -> 0.245
A55: =SVI!F55 -> Tarauacá/AC | B55: =INDEX(tb_SVI[],MATCH(Table3[[#This Row],[ibge_cod]],tb_SVI[Município],0),1) -> AC | C55: =INDEX(tb_SVI[],MATCH(Table3[[#This Row],[city_name]],tb_SVI[city_name_uf],0),3) -> 1200609 | D55: BRA.1.21_1 | E55: =INDEX(tb_SVI[],MATCH(Table3[[#This Row],[city_name]],tb_SVI[city_name_uf],0),5) -> 43151 | F55: =INDEX(tb_MHDI[],MATCH(Table3[[#This Row],[city_name]],tb_MHDI[mun_uf],0),5) -> 0.539 | G55: =INDEX(tb_MHDI[],MATCH(Table3[[#This Row],[city_name]],tb_MHDI[mun_uf],0),6) -> 0.554 | H55: =INDEX(tb_MHDI[],MATCH(Table3[[#This Row],[city_name]],tb_MHDI[mun_uf],0),7) -> 0.72 | I55: =INDEX(tb_MHDI[],MATCH(Table3[[#This Row],[city_name]],tb_MHDI[mun_uf],0),8) -> 0.392 | J55: =_xlfn.NUMBERVALUE(INDEX(tb_SVI[],MATCH(Table3[[#This Row],[city_name]],tb_SVI[city_name_uf],0),8),".") -> 0.585 | K55: =_xlfn.NUMBERVALUE(INDEX(tb_SVI[],MATCH(Table3[[#This Row],[city_name]],tb_SVI[city_name_uf],0),9),".") -> 0.46 | L55: =_xlfn.NUMBERVALUE(INDEX(tb_SVI[],MATCH(Table3[[#This Row],[city_name]],tb_SVI[city_name_uf],0),10),".") -> 0.773 | M55: =_xlfn.NUMBERVALUE(INDEX(tb_SVI[],MATCH(Table3[[#This Row],[city_name]],tb_SVI[city_name_uf],0),11),".") -> 0.522 | N55: =_xlfn.PERCENTRANK.INC(Table3[MHDI_tot],Table3[[#This Row],[MHDI_tot]],3) -> 0.04
A56: =SVI!F56 -> Senador Guiomard/AC | B56: =INDEX(tb_SVI[],MATCH(Table3[[#This Row],[ibge_cod]],tb_SVI[Município],0),1) -> AC | C56: =INDEX(tb_SVI[],MATCH(Table3[[#This Row],[city_name]],tb_SVI[city_name_uf],0),3) -> 1200450 | D56: BRA.1.20_1 | E56: =INDEX(tb_SVI[],MATCH(Table3[[#This Row],[city_name]],tb_SVI[city_name_uf],0),5) -> 23236 | F56: =INDEX(tb_MHDI[],MATCH(Table3[[#This Row],[city_name]],tb_MHDI[mun_uf],0),5) -> 0.64 | G56: =INDEX(tb_MHDI[],MATCH(Table3[[#This Row],[city_name]],tb_MHDI[mun_uf],0),6) -> 0.649 | H56: =INDEX(tb_MHDI[],MATCH(Table3[[#This Row],[city_name]],tb_MHDI[mun_uf],0),7) -> 0.786 | I56: =INDEX(tb_MHDI[],MATCH(Table3[[#This Row],[city_name]],tb_MHDI[mun_uf],0),8) -> 0.513 | J56: =_xlfn.NUMBERVALUE(INDEX(tb_SVI[],MATCH(Table3[[#This Row],[city_name]],tb_SVI[city_name_uf],0),8),".") -> 0.431 | K56: =_xlfn.NUMBERVALUE(INDEX(tb_SVI[],MATCH(Table3[[#This Row],[city_name]],tb_SVI[city_name_uf],0),9),".") -> 0.335 | L56: =_xlfn.NUMBERVALUE(INDEX(tb_SVI[],MATCH(Table3[[#This Row],[city_name]],tb_SVI[city_name_uf],0),10),".") -> 0.574 | M56: =_xlfn.NUMBERVALUE(INDEX(tb_SVI[],MATCH(Table3[[#This Row],[city_name]],tb_SVI[city_name_uf],0),11),".") -> 0.384 | N56: =_xlfn.PERCENTRANK.INC(Table3[MHDI_tot],Table3[[#This Row],[MHDI_tot]],3) -> 0.405
A57: =SVI!F57 -> Sena Madureira/AC | B57: =INDEX(tb_SVI[],MATCH(Table3[[#This Row],[ibge_cod]],tb_SVI[Município],0),1) -> AC | C57: =INDEX(tb_SVI[],MATCH(Table3[[#This Row],[city_name]],tb_SVI[city_name_uf],0),3) -> 1200500 | D57: BRA.1.19_1 | E57: =INDEX(tb_SVI[],MATCH(Table3[[#This Row],[city_name]],tb_SVI[city_name_uf],0),5) -> 46511 | F57: =INDEX(tb_MHDI[],MATCH(Table3[[#This Row],[city_name]],tb_MHDI[mun_uf],0),5) -> 0.603 | G57: =INDEX(tb_MHDI[],MATCH(Table3[[#This Row],[city_name]],tb_MHDI[mun_uf],0),6) -> 0.593 | H57: =INDEX(tb_MHDI[],MATCH(Table3[[#This Row],[city_name]],tb_MHDI[mun_uf],0),7) -> 0.81 | I57: =INDEX(tb_MHDI[],MATCH(Table3[[#This Row],[city_name]],tb_MHDI[mun_uf],0),8) -> 0.456 | J57: =_xlfn.NUMBERVALUE(INDEX(tb_SVI[],MATCH(Table3[[#This Row],[city_name]],tb_SVI[city_name_uf],0),8),".") -> 0.563 | K57: =_xlfn.NUMBERVALUE(INDEX(tb_SVI[],MATCH(Table3[[#This Row],[city_name]],tb_SVI[city_name_uf],0),9),".") -> 0.475 | L57: =_xlfn.NUMBERVALUE(INDEX(tb_SVI[],MATCH(Table3[[#This Row],[city_name]],tb_SVI[city_name_uf],0),10),".") -> 0.715 | M57: =_xlfn.NUMBERVALUE(INDEX(tb_SVI[],MATCH(Table3[[#This Row],[city_name]],tb_SVI[city_name_uf],0),11),".") -> 0.498 | N57: =_xlfn.PERCENTRANK.INC(Table3[MHDI_tot],Table3[[#This Row],[MHDI_tot]],3) -> 0.263
... A66: =SVI!F66 -> Manoel Urbano/AC | B66: =INDEX(tb_SVI[],MATCH(Table3[[#This Row],[ibge_cod]],tb_SVI[Município],0),1) -> AC | C66: =INDEX(tb_SVI[],MATCH(Table3[[#This Row],[city_name]],tb_SVI[city_name_uf],0),3) -> 1200344 | D66: BRA.1.11_1 | E66: =INDEX(tb_SVI[],MATCH(Table3[[#This Row],[city_name]],tb_SVI[city_name_uf],0),5) -> 9581 | F66: =INDEX(tb_MHDI[],MATCH(Table3[[#This Row],[city_name]],tb_MHDI[mun_uf],0),5) -> 0.551 | G66: =INDEX(tb_MHDI[],MATCH(Table3[[#This Row],[city_name]],tb_MHDI[mun_uf],0),6) -> 0.586 | H66: =INDEX(tb_MHDI[],MATCH(Table3[[#This Row],[city_name]],tb_MHDI[mun_uf],0),7) -> 0.767 | I66: =INDEX(tb_MHDI[],MATCH(Table3[[#This Row],[city_name]],tb_MHDI[mun_uf],0),8) -> 0.373 | J66: =_xlfn.NUMBERVALUE(INDEX(tb_SVI[],MATCH(Table3[[#This Row],[city_name]],tb_SVI[city_name_uf],0),8),".") -> 0.589 | K66: =_xlfn.NUMBERVALUE(INDEX(tb_SVI[],MATCH(Table3[[#This Row],[city_name]],tb_SVI[city_name_uf],0),9),".") -> 0.531 | L66: =_xlfn.NUMBERVALUE(INDEX(tb_SVI[],MATCH(Table3[[#This Row],[city_name]],tb_SVI[city_name_uf],0),10),".") -> 0.775 | M66: =_xlfn.NUMBERVALUE(INDEX(tb_SVI[],MATCH(Table3[[#This Row],[city_name]],tb_SVI[city_name_uf],0),11),".") -> 0.461 | N66: =_xlfn.PERCENTRANK.INC(Table3[MHDI_tot],Table3[[#This Row],[MHDI_tot]],3) -> 0.066
A67: =SVI!F180 -> Bagre/PA | B67: =INDEX(tb_SVI[],MATCH(Table3[[#This Row],[ibge_cod]],tb_SVI[Município],0),1) -> PA | C67: =INDEX(tb_SVI[],MATCH(Table3[[#This Row],[city_name]],tb_SVI[city_name_uf],0),3) -> 1501105 | D67: BRA.14.15_1 | E67: =INDEX(tb_SVI[],MATCH(Table3[[#This Row],[city_name]],tb_SVI[city_name_uf],0),5) -> 31325 | F67: =INDEX(tb_MHDI[],MATCH(Table3[[#This Row],[city_name]],tb_MHDI[mun_uf],0),5) -> 0.471 | G67: =INDEX(tb_MHDI[],MATCH(Table3[[#This Row],[city_name]],tb_MHDI[mun_uf],0),6) -> 0.481 | H67: =INDEX(tb_MHDI[],MATCH(Table3[[#This Row],[city_name]],tb_MHDI[mun_uf],0),7) -> 0.777 | I67: =INDEX(tb_MHDI[],MATCH(Table3[[#This Row],[city_name]],tb_MHDI[mun_uf],0),8) -> 0.28 | J67: =_xlfn.NUMBERVALUE(INDEX(tb_SVI[],MATCH(Table3[[#This Row],[city_name]],tb_SVI[city_name_uf],0),8),".") -> 0.676 | K67: =_xlfn.NUMBERVALUE(INDEX(tb_SVI[],MATCH(Table3[[#This Row],[city_name]],tb_SVI[city_name_uf],0),9),".") -> 0.617 | L67: =_xlfn.NUMBERVALUE(INDEX(tb_SVI[],MATCH(Table3[[#This Row],[city_name]],tb_SVI[city_name_uf],0),10),".") -> 0.74 | M67: =_xlfn.NUMBERVALUE(INDEX(tb_SVI[],MATCH(Table3[[#This Row],[city_name]],tb_SVI[city_name_uf],0),11),".") -> 0.672 | N67: =_xlfn.PERCENTRANK.INC(Table3[MHDI_tot],Table3[[#This Row],[MHDI_tot]],3) -> 0.001
A68: =SVI!F68 -> Feijó/AC | B68: =INDEX(tb_SVI[],MATCH(Table3[[#This Row],[ibge_cod]],tb_SVI[Município],0),1) -> AC | C68: =INDEX(tb_SVI[],MATCH(Table3[[#This Row],[city_name]],tb_SVI[city_name_uf],0),3) -> 1200302 | D68: BRA.1.8_1 | E68: =INDEX(tb_SVI[],MATCH(Table3[[#This Row],[city_name]],tb_SVI[city_name_uf],0),5) -> 34884 | F68: =INDEX(tb_MHDI[],MATCH(Table3[[#This Row],[city_name]],tb_MHDI[mun_uf],0),5) -> 0.539 | G68: =INDEX(tb_MHDI[],MATCH(Table3[[#This Row],[city_name]],tb_MHDI[mun_uf],0),6) -> 0.559 | H68: =INDEX(tb_MHDI[],MATCH(Table3[[#This Row],[city_name]],tb_MHDI[mun_uf],0),7) -> 0.723 | I68: =INDEX(tb_MHDI[],MATCH(Table3[[#This Row],[city_name]],tb_MHDI[mun_uf],0),8) -> 0.388 | J68: =_xlfn.NUMBERVALUE(INDEX(tb_SVI[],MATCH(Table3[[#This Row],[city_name]],tb_SVI[city_name_uf],0),8),".") -> 0.639 | K68: =_xlfn.NUMBERVALUE(INDEX(tb_SVI[],MATCH(Table3[[#This Row],[city_name]],tb_SVI[city_name_uf],0),9),".") -> 0.511 | L68: =_xlfn.NUMBERVALUE(INDEX(tb_SVI[],MATCH(Table3[[#This Row],[city_name]],tb_SVI[city_name_uf],0),10),".") -> 0.799 | M68: =_xlfn.NUMBERVALUE(INDEX(tb_SVI[],MATCH(Table3[[#This Row],[city_name]],tb_SVI[city_name_uf],0),11),".") -> 0.607 | N68: =_xlfn.PERCENTRANK.INC(Table3[MHDI_tot],Table3[[#This Row],[MHDI_tot]],3) -> 0.04
A69: =SVI!F69 -> Epitaciolândia/AC | B69: =INDEX(tb_SVI[],MATCH(Table3[[#This Row],[ibge_cod]],tb_SVI[Município],0),1) -> AC | C69: =INDEX(tb_SVI[],MATCH(Table3[[#This Row],[city_name]],tb_SVI[city_name_uf],0),3) -> 1200252 | D69: BRA.1.7_1 | E69: =INDEX(tb_SVI[],MATCH(Table3[[#This Row],[city_name]],tb_SVI[city_name_uf],0),5) -> 18696 | F69: =INDEX(tb_MHDI[],MATCH(Table3[[#This Row],[city_name]],tb_MHDI[mun_uf],0),5) -> 0.653 | G69: =INDEX(tb_MHDI[],MATCH(Table3[[#This Row],[city_name]],tb_MHDI[mun_uf],0),6) -> 0.654 | H69: =INDEX(tb_MHDI[],MATCH(Table3[[#This Row],[city_name]],tb_MHDI[mun_uf],0),7) -> 0.771 | I69: =INDEX(tb_MHDI[],MATCH(Table3[[#This Row],[city_name]],tb_MHDI[mun_uf],0),8) -> 0.553 | J69: =_xlfn.NUMBERVALUE(INDEX(tb_SVI[],MATCH(Table3[[#This Row],[city_name]],tb_SVI[city_name_uf],0),8),".") -> 0.441 | K69: =_xlfn.NUMBERVALUE(INDEX(tb_SVI[],MATCH(Table3[[#This Row],[city_name]],tb_SVI[city_name_uf],0),9),".") -> 0.379 | L69: =_xlfn.NUMBERVALUE(INDEX(tb_SVI[],MATCH(Table3[[#This Row],[city_name]],tb_SVI[city_name_uf],0),10),".") -> 0.517 | M69: =_xlfn.NUMBERVALUE(INDEX(tb_SVI[],MATCH(Table3[[#This Row],[city_name]],tb_SVI[city_name_uf],0),11),".") -> 0.427 | N69: =_xlfn.PERCENTRANK.INC(Table3[MHDI_tot],Table3[[#This Row],[MHDI_tot]],3) -> 0.448
A70: =SVI!F70 -> Cruzeiro do Sul/AC | B70: =INDEX(tb_SVI[],MATCH(Table3[[#This Row],[ibge_cod]],tb_SVI[Município],0),1) -> AC | C70: =INDEX(tb_SVI[],MATCH(Table3[[#This Row],[city_name]],tb_SVI[city_name_uf],0),3) -> 1200203 | D70: BRA.1.6_1 | E70: =INDEX(tb_SVI[],MATCH(Table3[[#This Row],[city_name]],tb_SVI[city_name_uf],0),5) -> 89072 | F70: =INDEX(tb_MHDI[],MATCH(Table3[[#This Row],[city_name]],tb_MHDI[mun_uf],0),5) -> 0.664 | G70: =INDEX(tb_MHDI[],MATCH(Table3[[#This Row],[city_name]],tb_MHDI[mun_uf],0),6) -> 0.648 | H70: =INDEX(tb_MHDI[],MATCH(Table3[[#This Row],[city_name]],tb_MHDI[mun_uf],0),7) -> 0.776 | I70: =INDEX(tb_MHDI[],MATCH(Table3[[#This Row],[city_name]],tb_MHDI[mun_uf],0),8) -> 0.582 | J70: =_xlfn.NUMBERVALUE(INDEX(tb_SVI[],MATCH(Table3[[#This Row],[city_name]],tb_SVI[city_name_uf],0),8),".") -> 0.475 | K70: =_xlfn.NUMBERVALUE(INDEX(tb_SVI[],MATCH(Table3[[#This Row],[city_name]],tb_SVI[city_name_uf],0),9),".") -> 0.445 | L70: =_xlfn.NUMBERVALUE(INDEX(tb_SVI[],MATCH(Table3[[#This Row],[city_name]],tb_SVI[city_name_uf],0),10),".") -> 0.559 | M70: =_xlfn.NUMBERVALUE(INDEX(tb_SVI[],MATCH(Table3[[#This Row],[city_name]],tb_SVI[city_name_uf],0),11),".") -> 0.42 | N70: =_xlfn.PERCENTRANK.INC(Table3[MHDI_tot],Table3[[#This Row],[MHDI_tot]],3) -> 0.492
A71: =SVI!F71 -> Capixaba/AC | B71: =INDEX(tb_SVI[],MATCH(Table3[[#This Row],[ibge_cod]],tb_SVI[Município],0),1) -> AC | C71: =INDEX(tb_SVI[],MATCH(Table3[[#This Row],[city_name]],tb_SVI[city_name_uf],0),3) -> 1200179 | D71: BRA.1.5_1 | E71: =INDEX(tb_SVI[],MATCH(Table3[[#This Row],[city_name]],tb_SVI[city_name_uf],0),5) -> 12008 | F71: =INDEX(tb_MHDI[],MATCH(Table3[[#This Row],[city_name]],tb_MHDI[mun_uf],0),5) -> 0.575 | G71: =INDEX(tb_MHDI[],MATCH(Table3[[#This Row],[city_name]],tb_MHDI[mun_uf],0),6) -> 0.601 | H71: =INDEX(tb_MHDI[],MATCH(Table3[[#This Row],[city_name]],tb_MHDI[mun_uf],0),7) -> 0.794 | I71: =INDEX(tb_MHDI[],MATCH(Table3[[#This Row],[city_name]],tb_MHDI[mun_uf],0),8) -> 0.398 | J71: =_xlfn.NUMBERVALUE(INDEX(tb_SVI[],MATCH(Table3[[#This Row],[city_name]],tb_SVI[city_name_uf],0),8),".") -> 0.469 | K71: =_xlfn.NUMBERVALUE(INDEX(tb_SVI[],MATCH(Table3[[#This Row],[city_name]],tb_SVI[city_name_uf],0),9),".") -> 0.302 | L71: =_xlfn.NUMBERVALUE(INDEX(tb_SVI[],MATCH(Table3[[#This Row],[city_name]],tb_SVI[city_name_uf],0),10),".") -> 0.612 | M71: =_xlfn.NUMBERVALUE(INDEX(tb_SVI[],MATCH(Table3[[#This Row],[city_name]],tb_SVI[city_name_uf],0),11),".") -> 0.493 | N71: =_xlfn.PERCENTRANK.INC(Table3[MHDI_tot],Table3[[#This Row],[MHDI_tot]],3) -> 0.144
A72: =SVI!F72 -> Bujari/AC | B72: =INDEX(tb_SVI[],MATCH(Table3[[#This Row],[ibge_cod]],tb_SVI[Município],0),1) -> AC | C72: =INDEX(tb_SVI[],MATCH(Table3[[#This Row],[city_name]],tb_SVI[city_name_uf],0),3) -> 1200138 | D72: BRA.1.4_1 | E72: =INDEX(tb_SVI[],MATCH(Table3[[#This Row],[city_name]],tb_SVI[city_name_uf],0),5) -> 10420 | F72: =INDEX(tb_MHDI[],MATCH(Table3[[#This Row],[city_name]],tb_MHDI[mun_uf],0),5) -> 0.589 | G72: =INDEX(tb_MHDI[],MATCH(Table3[[#This Row],[city_name]],tb_MHDI[mun_uf],0),6) -> 0.603 | H72: =INDEX(tb_MHDI[],MATCH(Table3[[#This Row],[city_name]],tb_MHDI[mun_uf],0),7) -> 0.772 | I72: =INDEX(tb_MHDI[],MATCH(Table3[[#This Row],[city_name]],tb_MHDI[mun_uf],0),8) -> 0.439 | J72: =_xlfn.NUMBERVALUE(INDEX(tb_SVI[],MATCH(Table3[[#This Row],[city_name]],tb_SVI[city_name_uf],0),8),".") -> 0.459 | K72: =_xlfn.NUMBERVALUE(INDEX(tb_SVI[],MATCH(Table3[[#This Row],[city_name]],tb_SVI[city_name_uf],0),9),".") -> 0.35 | L72: =_xlfn.NUMBERVALUE(INDEX(tb_SVI[],MATCH(Table3[[#This Row],[city_name]],tb_SVI[city_name_uf],0),10),".") -> 0.603 | M72: =_xlfn.NUMBERVALUE(INDEX(tb_SVI[],MATCH(Table3[[#This Row],[city_name]],tb_SVI[city_name_uf],0),11),".") -> 0.425 | N72: =_xlfn.PERCENTRANK.INC(Table3[MHDI_tot],Table3[[#This Row],[MHDI_tot]],3) -> 0.201
A73: =SVI!F73 -> Brasiléia/AC | B73: =INDEX(tb_SVI[],MATCH(Table3[[#This Row],[ibge_cod]],tb_SVI[Município],0),1) -> AC | C73: =INDEX(tb_SVI[],MATCH(Table3[[#This Row],[city_name]],tb_SVI[city_name_uf],0),3) -> 1200104 | D73: BRA.1.3_1 | E73: =INDEX(tb_SVI[],MATCH(Table3[[#This Row],[city_name]],tb_SVI[city_name_uf],0),5) -> 26702 | F73: =INDEX(tb_MHDI[],MATCH(Table3[[#This Row],[city_name]],tb_MHDI[mun_uf],0),5) -> 0.614 | G73: =INDEX(tb_MHDI[],MATCH(Table3[[#This Row],[city_name]],tb_MHDI[mun_uf],0),6) -> 0.619 | H73: =INDEX(tb_MHDI[],MATCH(Table3[[#This Row],[city_name]],tb_MHDI[mun_uf],0),7) -> 0.77 | I73: =INDEX(tb_MHDI[],MATCH(Table3[[#This Row],[city_name]],tb_MHDI[mun_uf],0),8) -> 0.485 | J73: =_xlfn.NUMBERVALUE(INDEX(tb_SVI[],MATCH(Table3[[#This Row],[city_name]],tb_SVI[city_name_uf],0),8),".") -> 0.462 | K73: =_xlfn.NUMBERVALUE(INDEX(tb_SVI[],MATCH(Table3[[#This Row],[city_name]],tb_SVI[city_name_uf],0),9),".") -> 0.32 | L73: =_xlfn.NUMBERVALUE(INDEX(tb_SVI[],MATCH(Table3[[#This Row],[city_name]],tb_SVI[city_name_uf],0),10),".") -> 0.593 | M73: =_xlfn.NUMBERVALUE(INDEX(tb_SVI[],MATCH(Table3[[#This Row],[city_name]],tb_SVI[city_name_uf],0),11),".") -> 0.473 | N73: =_xlfn.PERCENTRANK.INC(Table3[MHDI_tot],Table3[[#This Row],[MHDI_tot]],3) -> 0.308
...

Sheet SVI
A1: UF | B1: Nome da UF | C1: Município | D1: Nome Município | E1: pop_IBGE2020 | F1: city_name_uf | G1: Ano | H1: SVI | I1: SVI_infra | J1: SVI_hum | K1: SVI_wrk
A2: =INDEX(UF_acronyms!$A$1:$C$28,MATCH(B2,UF_acronyms!$C$1:$C$28,0),2) -> RO | B2: Rondônia | C2: 1100072 | D2: Corumbiara | E2: 7220 | F2: =CONCATENATE(tb_SVI[[#This Row],[Nome Município]],"/",tb_SVI[[#This Row],[UF]]) -> Corumbiara/RO | G2: 2010 | H2: 0.336 | I2: 0.201 | J2: 0.427 | K2: 0.381
A3: =INDEX(UF_acronyms!$A$1:$C$28,MATCH(B3,UF_acronyms!$C$1:$C$28,0),2) -> RO | B3: Rondônia | C3: 1100064 | D3: Colorado do Oeste | E3: 15544 | F3: =CONCATENATE(tb_SVI[[#This Row],[Nome Município]],"/",tb_SVI[[#This Row],[UF]]) -> Colorado do Oeste/RO | G3: 2010 | H3: 0.28 | I3: 0.114 | J3: 0.394 | K3: 0.333
A4: =INDEX(UF_acronyms!$A$1:$C$28,MATCH(B4,UF_acronyms!$C$1:$C$28,0),2) -> RO | B4: Rondônia | C4: 1100924 | D4: Chupinguaia | E4: 11472 | F4: =CONCATENATE(tb_SVI[[#This Row],[Nome Município]],"/",tb_SVI[[#This Row],[UF]]) -> Chupinguaia/RO | G4: 2010 | H4: 0.338 | I4: 0.285 | J4: 0.383 | K4: 0.347
A5: =INDEX(UF_acronyms!$A$1:$C$28,MATCH(B5,UF_acronyms!$C$1:$C$28,0),2) -> RO | B5: Rondônia | C5: 1100304 | D5: Vilhena | E5: 102211 | F5: =CONCATENATE(tb_SVI[[#This Row],[Nome Município]],"/",tb_SVI[[#This Row],[UF]]) -> Vilhena/RO | G5: 2010 | H5: 0.239 | I5: 0.103 | J5: 0.339 | K5: 0.274
A6: =INDEX(UF_acronyms!$A$1:$C$28,MATCH(B6,UF_acronyms!$C$1:$C$28,0),2) -> RO | B6: Rondônia | C6: 1101807 | D6: Vale do Paraíso | E6: 6656 | F6: =CONCATENATE(tb_SVI[[#This Row],[Nome Município]],"/",tb_SVI[[#This Row],[UF]]) -> Vale do Paraíso/RO | G6: 2010 | H6: 0.309 | I6: 0.131 | J6: 0.438 | K6: 0.358
A7: =INDEX(UF_acronyms!$A$1:$C$28,MATCH(B7,UF_acronyms!$C$1:$C$28,0),2) -> RO | B7: Rondônia | C7: 1101757 | D7: Vale do Anari | E7: 11377 | F7: =CONCATENATE(tb_SVI[[#This Row],[Nome Município]],"/",tb_SVI[[#This Row],[UF]]) -> Vale do Anari/RO | G7: 2010 | H7: 0.402 | I7: 0.200 | J7: 0.526 | K7: 0.481
A8: =INDEX(UF_acronyms!$A$1:$C$28,MATCH(B8,UF_acronyms!$C$1:$C$28,0),2) -> RO | B8: Rondônia | C8: 1101708 | D8: Urupá | E8: 11272 | F8: =CONCATENATE(tb_SVI[[#This Row],[Nome Município]],"/",tb_SVI[[#This Row],[UF]]) -> Urupá/RO | G8: 2010 | H8: 0.386 | I8: 0.194 | J8: 0.445 | K8: 0.520
A9: =INDEX(UF_acronyms!$A$1:$C$28,MATCH(B9,UF_acronyms!$C$1:$C$28,0),2) -> RO | B9: Rondônia | C9: 1101609 | D9: Theobroma | E9: 10395 | F9: =CONCATENATE(tb_SVI[[#This Row],[Nome Município]],"/",tb_SVI[[#This Row],[UF]]) -> Theobroma/RO | G9: 2010 | H9: 0.352 | I9: 0.164 | J9: 0.388 | K9: 0.505
A10: =INDEX(UF_acronyms!$A$1:$C$28,MATCH(B10,UF_acronyms!$C$1:$C$28,0),2) -> RO | B10: Rondônia | C10: 1101559 | D10: Teixeirópolis | E10: 4233 | F10: =CONCATENATE(tb_SVI[[#This Row],[Nome Município]],"/",tb_SVI[[#This Row],[UF]]) -> Teixeirópolis/RO | G10: 2010 | H10: 0.299 | I10: 0.197 | J10: 0.322 | K10: 0.377
A11: =INDEX(UF_acronyms!$A$1:$C$28,MATCH(B11,UF_acronyms!$C$1:$C$28,0),2) -> RO | B11: Rondônia | C11: 1100320 | D11: São Miguel do Guaporé | E11: 23077 | F11: =CONCATENATE(tb_SVI[[#This Row],[Nome Município]],"/",tb_SVI[[#This Row],[UF]]) -> São Miguel do Guaporé/RO | G11: 2010 | H11: 0.338 | I11: 0.127 | J11: 0.466 | K11: 0.421
A12: =INDEX(UF_acronyms!$A$1:$C$28,MATCH(B12,UF_acronyms!$C$1:$C$28,0),2) -> RO | B12: Rondônia | C12: 1101492 | D12: São Francisco do Guaporé | E12: 20681 | F12: =CONCATENATE(tb_SVI[[#This Row],[Nome Município]],"/",tb_SVI[[#This Row],[UF]]) -> São Francisco do Guaporé/RO | G12: 2010 | H12: 0.429 | I12: 0.282 | J12: 0.554 | K12: 0.451
A13: =INDEX(UF_acronyms!$A$1:$C$28,MATCH(B13,UF_acronyms!$C$1:$C$28,0),2) -> RO | B13: Rondônia | C13: 1101484 | D13: São Felipe D'Oeste | E13: 5066 | F13: =CONCATENATE(tb_SVI[[#This Row],[Nome Município]],"/",tb_SVI[[#This Row],[UF]]) -> São Felipe D'Oeste/RO | G13: 2010 | H13: 0.338 | I13: 0.159 | J13: 0.447 | K13: 0.407
... A5566: =INDEX(UF_acronyms!$A$1:$C$28,MATCH(B5566,UF_acronyms!$C$1:$C$28,0),2) -> DF | B5566: Distrito Federal | C5566: 5300108 | D5566: Brasília | E5566: 3055149 | F5566: =CONCATENATE(tb_SVI[[#This Row],[Nome Município]],"/",tb_SVI[[#This Row],[UF]]) -> Brasília/DF | G5566: 2010 | H5566: 0.294 | I5566: 0.412 | J5566: 0.265 | K5566: 0.204

Sheet MHDI
A1: Territorialidades | B1: Município | C1: UF | D1: mun_uf | E1: IDHM 2010 | F1: IDHM Renda 2010 | G1: IDHM Longevidade 2010 | H1: IDHM Educação 2010 | I1: IDHM Educação 2011
A2: Abadia de Goiás /GO) | B2: =LEFT(tb_MHDI[[#This Row],[Territorialidades]],(FIND("/",tb_MHDI[[#This Row],[Territorialidades]])-2)) -> Abadia de Goiás | C2: =LEFT(RIGHT(tb_MHDI[[#This Row],[Territorialidades]],3),2) -> GO | D2: =CONCATENATE(tb_MHDI[[#This Row],[Município]],"/",tb_MHDI[[#This Row],[UF]]) -> Abadia de Goiás/GO | E2: 0.708 | F2: 0.687 | G2: 0.83 | H2: 0.622 | I2: =_xlfn.NUMBERVALUE(INDEX(tb_SVI[],MATCH(tb_MHDI[[#This Row],[mun_uf]],tb_SVI[city_name_uf],0),7),".") -> 2010
A3: Abadia dos Dourados /MG) | B3: =LEFT(tb_MHDI[[#This Row],[Territorialidades]],(FIND("/",tb_MHDI[[#This Row],[Territorialidades]])-2)) -> Abadia dos Dourados | C3: =LEFT(RIGHT(tb_MHDI[[#This Row],[Territorialidades]],3),2) -> MG | D3: =CONCATENATE(tb_MHDI[[#This Row],[Município]],"/",tb_MHDI[[#This Row],[UF]]) -> Abadia dos Dourados/MG | E3: 0.689 | F3: 0.693 | G3: 0.839 | H3: 0.563 | I3: =_xlfn.NUMBERVALUE(INDEX(tb_SVI[],MATCH(tb_MHDI[[#This Row],[mun_uf]],tb_SVI[city_name_uf],0),7),".") -> 2010
A4: Abadiânia /GO) | B4: =LEFT(tb_MHDI[[#This Row],[Territorialidades]],(FIND("/",tb_MHDI[[#This Row],[Territorialidades]])-2)) -> Abadiânia | C4: =LEFT(RIGHT(tb_MHDI[[#This Row],[Territorialidades]],3),2) -> GO | D4: =CONCATENATE(tb_MHDI[[#This Row],[Município]],"/",tb_MHDI[[#This Row],[UF]]) -> Abadiânia/GO | E4: 0.689 | F4: 0.671 | G4: 0.841 | H4: 0.579 | I4: =_xlfn.NUMBERVALUE(INDEX(tb_SVI[],MATCH(tb_MHDI[[#This Row],[mun_uf]],tb_SVI[city_name_uf],0),7),".") -> 2010
A5: Abaeté /MG) | B5: =LEFT(tb_MHDI[[#This Row],[Territorialidades]],(FIND("/",tb_MHDI[[#This Row],[Territorialidades]])-2)) -> Abaeté | C5: =LEFT(RIGHT(tb_MHDI[[#This Row],[Territorialidades]],3),2) -> MG | D5: =CONCATENATE(tb_MHDI[[#This Row],[Município]],"/",tb_MHDI[[#This Row],[UF]]) -> Abaeté/MG | E5: 0.698 | F5: 0.72 | G5: 0.848 | H5: 0.556 | I5: =_xlfn.NUMBERVALUE(INDEX(tb_SVI[],MATCH(tb_MHDI[[#This Row],[mun_uf]],tb_SVI[city_name_uf],0),7),".") -> 2010
A6: Abaetetuba /PA) | B6: =LEFT(tb_MHDI[[#This Row],[Territorialidades]],(FIND("/",tb_MHDI[[#This Row],[Territorialidades]])-2)) -> Abaetetuba | C6: =LEFT(RIGHT(tb_MHDI[[#This Row],[Territorialidades]],3),2) -> PA | D6: =CONCATENATE(tb_MHDI[[#This Row],[Município]],"/",tb_MHDI[[#This Row],[UF]]) -> Abaetetuba/PA | E6: 0.628 | F6: 0.579 | G6: 0.798 | H6: 0.537 | I6: =_xlfn.NUMBERVALUE(INDEX(tb_SVI[],MATCH(tb_MHDI[[#This Row],[mun_uf]],tb_SVI[city_name_uf],0),7),".") -> 2010
A7: Abaiara /CE) | B7: =LEFT(tb_MHDI[[#This Row],[Territorialidades]],(FIND("/",tb_MHDI[[#This Row],[Territorialidades]])-2)) -> Abaiara | C7: =LEFT(RIGHT(tb_MHDI[[#This Row],[Territorialidades]],3),2) -> CE | D7: =CONCATENATE(tb_MHDI[[#This Row],[Município]],"/",tb_MHDI[[#This Row],[UF]]) -> Abaiara/CE | E7: 0.628 | F7: 0.54 | G7: 0.748 | H7: 0.612 | I7: =_xlfn.NUMBERVALUE(INDEX(tb_SVI[],MATCH(tb_MHDI[[#This Row],[mun_uf]],tb_SVI[city_name_uf],0),7),".") -> 2010
A8: Abaíra /BA) | B8: =LEFT(tb_MHDI[[#This Row],[Territorialidades]],(FIND("/",tb_MHDI[[#This Row],[Territorialidades]])-2)) -> Abaíra | C8: =LEFT(RIGHT(tb_MHDI[[#This Row],[Territorialidades]],3),2) -> BA | D8: =CONCATENATE(tb_MHDI[[#This Row],[Município]],"/",tb_MHDI[[#This Row],[UF]]) -> Abaíra/BA | E8: 0.603 | F8: 0.577 | G8: 0.746 | H8: 0.51 | I8: =_xlfn.NUMBERVALUE(INDEX(tb_SVI[],MATCH(tb_MHDI[[#This Row],[mun_uf]],tb_SVI[city_name_uf],0),7),".") -> 2010
A9: Abaré /BA) | B9: =LEFT(tb_MHDI[[#This Row],[Territorialidades]],(FIND("/",tb_MHDI[[#This Row],[Territorialidades]])-2)) -> Abaré | C9: =LEFT(RIGHT(tb_MHDI[[#This Row],[Territorialidades]],3),2) -> BA | D9: =CONCATENATE(tb_MHDI[[#This Row],[Município]],"/",tb_MHDI[[#This Row],[UF]]) -> Abaré/BA | E9: 0.575 | F9: 0.533 | G9: 0.776 | H9: 0.46 | I9: =_xlfn.NUMBERVALUE(INDEX(tb_SVI[],MATCH(tb_MHDI[[#This Row],[mun_uf]],tb_SVI[city_name_uf],0),7),".") -> 2010
A10: Abatiá /PR) | B10: =LEFT(tb_MHDI[[#This Row],[Territorialidades]],(FIND("/",tb_MHDI[[#This Row],[Territorialidades]])-2)) -> Abatiá | C10: =LEFT(RIGHT(tb_MHDI[[#This Row],[Territorialidades]],3),2) -> PR | D10: =CONCATENATE(tb_MHDI[[#This Row],[Município]],"/",tb_MHDI[[#This Row],[UF]]) -> Abatiá/PR | E10: 0.687 | F10: 0.676 | G10: 0.804 | H10: 0.596 | I10: =_xlfn.NUMBERVALUE(INDEX(tb_SVI[],MATCH(tb_MHDI[[#This Row],[mun_uf]],tb_SVI[city_name_uf],0),7),".") -> 2010
A11: Abdon Batista /SC) | B11: =LEFT(tb_MHDI[[#This Row],[Territorialidades]],(FIND("/",tb_MHDI[[#This Row],[Territorialidades]])-2)) -> Abdon Batista | C11: =LEFT(RIGHT(tb_MHDI[[#This Row],[Territorialidades]],3),2) -> SC | D11: =CONCATENATE(tb_MHDI[[#This Row],[Município]],"/",tb_MHDI[[#This Row],[UF]]) -> Abdon Batista/SC | E11: 0.694 | F11: 0.66 | G11: 0.812 | H11: 0.625 | I11: =_xlfn.NUMBERVALUE(INDEX(tb_SVI[],MATCH(tb_MHDI[[#This Row],[mun_uf]],tb_SVI[city_name_uf],0),7),".") -> 2010
